<?xml version="1.0" ?>
<!-- =================================================================================== -->
<!-- |    This document was autogenerated by xacro from doggy.urdf.xacro               | -->
<!-- |    EDITING THIS FILE BY HAND IS NOT RECOMMENDED                                 | -->
<!-- =================================================================================== -->
<robot name="my_robot">
  <material name="green">
    <color rgba="0.3 1 0.3 1"/>
  </material>
  <material name="grey">
    <color rgba="0.5 0.5 0.5 1"/>
  </material>
  <!-- A inclusão do properties antes permite que seja usado em todos os arquivos abaixo -->
  <link name="body_link">
    <visual>
      <geometry>
        <box size="0.6 0.4 0.2"/>
      </geometry>
      <origin rpy="0 0 0" xyz="0 0 0.1"/>
      <material name="green"/>
    </visual>
    <collision>
      <geometry>
        <box size="0.6 0.4 0.2"/>
      </geometry>
      <origin rpy="0 0 0" xyz="0 0 0.1"/>
    </collision>
    <inertial>
      <origin rpy="0 0 0" xyz="0 0 0.1"/>
      <mass value="5.0"/>
      <inertia ixx="0.16666666666666669" ixy="0.0" ixz="0.0" iyy="0.21666666666666667" iyz="0.0" izz="0.08333333333333336"/>
    </inertial>
  </link>
  <link name="RR_upper_leg_link">
    <visual>
      <geometry>
        <cylinder length="0.15" radius="0.05"/>
      </geometry>
      <origin rpy="0 0 0" xyz="0 0 -0.075"/>
      <material name="grey"/>
    </visual>
    <collision>
      <geometry>
        <cylinder length="0.15" radius="0.05"/>
      </geometry>
      <origin rpy="0 0 0" xyz="0 0 -0.075"/>
    </collision>
    <inertial>
      <origin rpy="1.5707963267948966 0 0" xyz="0 0 0"/>
      <mass value="1.0"/>
      <inertia ixx="0.0024999999999999996" ixy="0.0" ixz="0.0" iyy="0.0024999999999999996" iyz="0.0" izz="0.0012500000000000002"/>
    </inertial>
  </link>
  <link name="RL_upper_leg_link">
    <visual>
      <geometry>
        <cylinder length="0.15" radius="0.05"/>
      </geometry>
      <origin rpy="0 0 0" xyz="0 0 -0.075"/>
      <material name="grey"/>
    </visual>
    <collision>
      <geometry>
        <cylinder length="0.15" radius="0.05"/>
      </geometry>
      <origin rpy="0 0 0" xyz="0 0 -0.075"/>
    </collision>
    <inertial>
      <origin rpy="1.5707963267948966 0 0" xyz="0 0 0"/>
      <mass value="1.0"/>
      <inertia ixx="0.0024999999999999996" ixy="0.0" ixz="0.0" iyy="0.0024999999999999996" iyz="0.0" izz="0.0012500000000000002"/>
    </inertial>
  </link>
  <link name="FR_upper_leg_link">
    <visual>
      <geometry>
        <cylinder length="0.15" radius="0.05"/>
      </geometry>
      <origin rpy="0 0 0" xyz="0 0 -0.075"/>
      <material name="grey"/>
    </visual>
    <collision>
      <geometry>
        <cylinder length="0.15" radius="0.05"/>
      </geometry>
      <origin rpy="0 0 0" xyz="0 0 -0.075"/>
    </collision>
    <inertial>
      <origin rpy="1.5707963267948966 0 0" xyz="0 0 0"/>
      <mass value="1.0"/>
      <inertia ixx="0.0024999999999999996" ixy="0.0" ixz="0.0" iyy="0.0024999999999999996" iyz="0.0" izz="0.0012500000000000002"/>
    </inertial>
  </link>
  <link name="FL_upper_leg_link">
    <visual>
      <geometry>
        <cylinder length="0.15" radius="0.05"/>
      </geometry>
      <origin rpy="0 0 0" xyz="0 0 -0.075"/>
      <material name="grey"/>
    </visual>
    <collision>
      <geometry>
        <cylinder length="0.15" radius="0.05"/>
      </geometry>
      <origin rpy="0 0 0" xyz="0 0 -0.075"/>
    </collision>
    <inertial>
      <origin rpy="1.5707963267948966 0 0" xyz="0 0 0"/>
      <mass value="1.0"/>
      <inertia ixx="0.0024999999999999996" ixy="0.0" ixz="0.0" iyy="0.0024999999999999996" iyz="0.0" izz="0.0012500000000000002"/>
    </inertial>
  </link>
  <joint name="RR_upper_leg_joint" type="continuous">
    <parent link="body_link"/>
    <child link="RR_upper_leg_link"/>
    <origin rpy="0 0 0" xyz="-0.2 -0.25 0.1"/>
    <axis xyz="0 1 0"/>
  </joint>
  <joint name="RL_upper_leg_joint" type="continuous">
    <parent link="body_link"/>
    <child link="RL_upper_leg_link"/>
    <origin rpy="0 0 0" xyz="-0.2 0.25 0.1"/>
    <axis xyz="0 1 0"/>
  </joint>
  <joint name="FR_upper_leg_joint" type="continuous">
    <parent link="body_link"/>
    <child link="FR_upper_leg_link"/>
    <origin rpy="0 0 0" xyz="0.2 -0.25 0.1"/>
    <axis xyz="0 1 0"/>
  </joint>
  <joint name="FL_upper_leg_joint" type="continuous">
    <parent link="body_link"/>
    <child link="FL_upper_leg_link"/>
    <origin rpy="0 0 0" xyz="0.2 0.25 0.1"/>
    <axis xyz="0 1 0"/>
  </joint>
  <link name="RR_lower_leg_link">
    <visual>
      <geometry>
        <cylinder length="0.15" radius="0.05"/>
      </geometry>
      <origin rpy="0 0 0" xyz="0 0 -0.075"/>
      <material name="grey"/>
    </visual>
    <collision>
      <geometry>
        <cylinder length="0.15" radius="0.05"/>
      </geometry>
      <origin rpy="0 0 0" xyz="0 0 -0.075"/>
    </collision>
    <inertial>
      <origin rpy="1.5707963267948966 0 0" xyz="0 0 0"/>
      <mass value="1.0"/>
      <inertia ixx="0.0024999999999999996" ixy="0.0" ixz="0.0" iyy="0.0024999999999999996" iyz="0.0" izz="0.0012500000000000002"/>
    </inertial>
  </link>
  <link name="RL_lower_leg_link">
    <visual>
      <geometry>
        <cylinder length="0.15" radius="0.05"/>
      </geometry>
      <origin rpy="0 0 0" xyz="0 0 -0.075"/>
      <material name="grey"/>
    </visual>
    <collision>
      <geometry>
        <cylinder length="0.15" radius="0.05"/>
      </geometry>
      <origin rpy="0 0 0" xyz="0 0 -0.075"/>
    </collision>
    <inertial>
      <origin rpy="1.5707963267948966 0 0" xyz="0 0 0"/>
      <mass value="1.0"/>
      <inertia ixx="0.0024999999999999996" ixy="0.0" ixz="0.0" iyy="0.0024999999999999996" iyz="0.0" izz="0.0012500000000000002"/>
    </inertial>
  </link>
  <link name="FR_lower_leg_link">
    <visual>
      <geometry>
        <cylinder length="0.15" radius="0.05"/>
      </geometry>
      <origin rpy="0 0 0" xyz="0 0 -0.075"/>
      <material name="grey"/>
    </visual>
    <collision>
      <geometry>
        <cylinder length="0.15" radius="0.05"/>
      </geometry>
      <origin rpy="0 0 0" xyz="0 0 -0.075"/>
    </collision>
    <inertial>
      <origin rpy="1.5707963267948966 0 0" xyz="0 0 0"/>
      <mass value="1.0"/>
      <inertia ixx="0.0024999999999999996" ixy="0.0" ixz="0.0" iyy="0.0024999999999999996" iyz="0.0" izz="0.0012500000000000002"/>
    </inertial>
  </link>
  <link name="FL_lower_leg_link">
    <visual>
      <geometry>
        <cylinder length="0.15" radius="0.05"/>
      </geometry>
      <origin rpy="0 0 0" xyz="0 0 -0.075"/>
      <material name="grey"/>
    </visual>
    <collision>
      <geometry>
        <cylinder length="0.15" radius="0.05"/>
      </geometry>
      <origin rpy="0 0 0" xyz="0 0 -0.075"/>
    </collision>
    <inertial>
      <origin rpy="1.5707963267948966 0 0" xyz="0 0 0"/>
      <mass value="1.0"/>
      <inertia ixx="0.0024999999999999996" ixy="0.0" ixz="0.0" iyy="0.0024999999999999996" iyz="0.0" izz="0.0012500000000000002"/>
    </inertial>
  </link>
  <joint name="RR_lower_leg_joint" type="continuous">
    <parent link="RR_upper_leg_link"/>
    <child link="RR_lower_leg_link"/>
    <origin rpy="0 0 0" xyz="0 0 -0.15"/>
    <axis xyz="0 1 0"/>
  </joint>
  <joint name="RL_lower_leg_joint" type="continuous">
    <parent link="RL_upper_leg_link"/>
    <child link="RL_lower_leg_link"/>
    <origin rpy="0 0 0" xyz="0 0 -0.15"/>
    <axis xyz="0 1 0"/>
  </joint>
  <joint name="FR_lower_leg_joint" type="continuous">
    <parent link="FR_upper_leg_link"/>
    <child link="FR_lower_leg_link"/>
    <origin rpy="0 0 0" xyz="0 0 -0.15"/>
    <axis xyz="0 1 0"/>
  </joint>
  <joint name="FL_lower_leg_joint" type="continuous">
    <parent link="FL_upper_leg_link"/>
    <child link="FL_lower_leg_link"/>
    <origin rpy="0 0 0" xyz="0 0 -0.15"/>
    <axis xyz="0 1 0"/>
  </joint>
  <link name="RR_foot_link">
    <visual>
      <geometry>
        <sphere radius="0.05"/>
        <origin rpy="0 0 0" xyz="0 0 0"/>
      </geometry>
      <material name="grey"/>
    </visual>
    <collision>
      <geometry>
        <sphere radius="0.05"/>
        <origin rpy="0 0 0" xyz="0 0 0"/>
      </geometry>
    </collision>
    <inertial>
      <origin rpy="0 0 0" xyz="0 0 0"/>
      <mass value="0.5"/>
      <inertia ixx="0.0005000000000000001" ixy="0.0" ixz="0.0" iyy="0.0005000000000000001" iyz="0.0" izz="0.0005000000000000001"/>
    </inertial>
  </link>
  <link name="RL_foot_link">
    <visual>
      <geometry>
        <sphere radius="0.05"/>
        <origin rpy="0 0 0" xyz="0 0 0"/>
      </geometry>
      <material name="grey"/>
    </visual>
    <collision>
      <geometry>
        <sphere radius="0.05"/>
        <origin rpy="0 0 0" xyz="0 0 0"/>
      </geometry>
    </collision>
    <inertial>
      <origin rpy="0 0 0" xyz="0 0 0"/>
      <mass value="0.5"/>
      <inertia ixx="0.0005000000000000001" ixy="0.0" ixz="0.0" iyy="0.0005000000000000001" iyz="0.0" izz="0.0005000000000000001"/>
    </inertial>
  </link>
  <link name="FR_foot_link">
    <visual>
      <geometry>
        <sphere radius="0.05"/>
        <origin rpy="0 0 0" xyz="0 0 0"/>
      </geometry>
      <material name="grey"/>
    </visual>
    <collision>
      <geometry>
        <sphere radius="0.05"/>
        <origin rpy="0 0 0" xyz="0 0 0"/>
      </geometry>
    </collision>
    <inertial>
      <origin rpy="0 0 0" xyz="0 0 0"/>
      <mass value="0.5"/>
      <inertia ixx="0.0005000000000000001" ixy="0.0" ixz="0.0" iyy="0.0005000000000000001" iyz="0.0" izz="0.0005000000000000001"/>
    </inertial>
  </link>
  <link name="FL_foot_link">
    <visual>
      <geometry>
        <sphere radius="0.05"/>
        <origin rpy="0 0 0" xyz="0 0 0"/>
      </geometry>
      <material name="grey"/>
    </visual>
    <collision>
      <geometry>
        <sphere radius="0.05"/>
        <origin rpy="0 0 0" xyz="0 0 0"/>
      </geometry>
    </collision>
    <inertial>
      <origin rpy="0 0 0" xyz="0 0 0"/>
      <mass value="0.5"/>
      <inertia ixx="0.0005000000000000001" ixy="0.0" ixz="0.0" iyy="0.0005000000000000001" iyz="0.0" izz="0.0005000000000000001"/>
    </inertial>
  </link>
  <joint name="RR_foot_joint" type="fixed">
    <parent link="RR_lower_leg_link"/>
    <child link="RR_foot_link"/>
    <origin rpy="0 0 0" xyz="0 0 -0.15"/>
  </joint>
  <joint name="RL_foot_joint" type="fixed">
    <parent link="RL_lower_leg_link"/>
    <child link="RL_foot_link"/>
    <origin rpy="0 0 0" xyz="0 0 -0.15"/>
  </joint>
  <joint name="FR_foot_joint" type="fixed">
    <parent link="FR_lower_leg_link"/>
    <child link="FR_foot_link"/>
    <origin rpy="0 0 0" xyz="0 0 -0.15"/>
  </joint>
  <joint name="FL_foot_joint" type="fixed">
    <parent link="FL_lower_leg_link"/>
    <child link="FL_foot_link"/>
    <origin rpy="0 0 0" xyz="0 0 -0.15"/>
  </joint>
</robot>
